Workbook

Sheet Raw
A1: Speed measurements template (timing gates)
A2: How to use: 1) Enter Participant, Activity, Trial #, Gate Distance (m), and Time Duration (s). 2) Speed (m/s) is computed automatically. Optional: add Notes. 3) The Summary sheet updates counts and mean speed by participant × activity. Tip: Keep Activity labels consistent (walking, jogging, running, heel_drop, step_drop).
A6: participant | B6: activity | C6: trial_num | D6: gate_distance_m | E6: time_s | F6: speed_mps | G6: speed_kmh | H6: notes
A7: P1 | B7: walking | C7: 1 | D7: 3.73 | E7: 2.52 | F7: =D7/E7 -> 1.4801587 | G7: =IF(F7="","",F7*3.6) -> 5.3285714 | H7: shoes size: 44
A8: P1 | B8: walking | C8: 2 | D8: 3.73 | E8: 2.15 | F8: =D8/E8 -> 1.7348837 | G8: =IF(F8="","",F8*3.6) -> 6.2455814
A9: P1 | B9: walking | C9: 3 | D9: 3.73 | E9: 2.26 | F9: =D9/E9 -> 1.6504425 | G9: =IF(F9="","",F9*3.6) -> 5.9415929
A10: P1 | B10: walking | C10: 4 | D10: 3.73 | E10: 2 | F10: =D10/E10 -> 1.865 | G10: =IF(F10="","",F10*3.6) -> 6.714
A11: P1 | B11: walking | C11: 5 | D11: 3.73 | E11: 2.12 | F11: =D11/E11 -> 1.759434 | G11: =IF(F11="","",F11*3.6) -> 6.3339623
A12: P1 | B12: walking | C12: 6 | D12: 3.73 | E12: 2.18 | F12: =D12/E12 -> 1.7110092 | G12: =IF(F12="","",F12*3.6) -> 6.159633
A13: P1 | B13: walking | C13: 7 | D13: 3.73 | E13: 2 | F13: =D13/E13 -> 1.865 | G13: =IF(F13="","",F13*3.6) -> 6.714
A14: P1 | B14: walking | C14: 8 | D14: 3.73 | E14: 2.2 | F14: =D14/E14 -> 1.6954545 | G14: =F14*3.6 -> 6.1036364
A15: P1 | B15: walking | C15: 9 | D15: 3.73 | E15: 2.33 | F15: =D15/E15 -> 1.6008584 | G15: =F15*3.6 -> 5.7630901
A16: P1 | B16: walking | C16: 10 | D16: 3.73 | E16: 2.08 | F16: =D16/E16 -> 1.7932692 | G16: =F16*3.6 -> 6.4557692
A17: P1 | B17: jogging | C17: 1 | D17: 3.73 | E17: 1.13 | F17: =D17/E17 -> 3.300885 | G17: =F17*3.6 -> 11.883186
A18: P1 | B18: jogging | C18: 2 | D18: 3.73 | E18: 1.07 | F18: =D18/E18 -> 3.4859813 | G18: =F18*3.6 -> 12.549533
A19: P1 | B19: jogging | C19: 3 | D19: 3.73 | E19: 0.99 | F19: =D19/E19 -> 3.7676768 | G19: =F19*3.6 -> 13.563636
A20: P1 | B20: jogging | C20: 4 | D20: 3.73 | E20: 1.07 | F20: =D20/E20 -> 3.4859813 | G20: =F20*3.6 -> 12.549533
A21: P1 | B21: jogging | C21: 5 | D21: 3.73 | E21: 1.22 | F21: =D21/E21 -> 3.057377 | G21: =F21*3.6 -> 11.006557
A22: P1 | B22: jogging | C22: 6 | D22: 3.73 | E22: 1.03 | F22: =D22/E22 -> 3.6213592 | G22: =F22*3.6 -> 13.036893
A23: P1 | B23: jogging | C23: 7 | D23: 3.73 | E23: 1.06 | F23: =D23/E23 -> 3.5188679 | G23: =F23*3.6 -> 12.667925
A24: P1 | B24: jogging | C24: 8 | D24: 3.73 | E24: 1.3 | F24: =D24/E24 -> 2.8692308 | G24: =F24*3.6 -> 10.329231
A25: P1 | B25: jogging | C25: 9 | D25: 3.73 | E25: 1.21 | F25: =D25/E25 -> 3.0826446 | G25: =F25*3.6 -> 11.097521
... A39: P1 | B39: running | C39: 12 | D39: 3.73 | E39: 0.84 | F39: =D39/E39 -> 4.4404762 | G39: =F39*3.6 -> 15.985714
A40: P2 | B40: walking | C40: 1 | D40: 3.95 | E40: 2.38 | F40: =D40/E40 -> 1.6596639 | G40: =F40*3.6 -> 5.9747899 | H40: shoes size: 40
A41: P2 | B41: walking | C41: 2 | D41: 3.95 | E41: 2.55 | F41: =D41/E41 -> 1.5490196 | G41: =F41*3.6 -> 5.5764706
A42: P2 | B42: walking | C42: 3 | D42: 3.95 | E42: 2.54 | F42: =D42/E42 -> 1.5551181 | G42: =F42*3.6 -> 5.5984252
A43: P2 | B43: walking | C43: 4 | D43: 3.95 | E43: 2.63 | F43: =D43/E43 -> 1.5019011 | G43: =F43*3.6 -> 5.4068441
A44: P2 | B44: walking | C44: 5 | D44: 3.95 | E44: 2.63 | F44: =D44/E44 -> 1.5019011 | G44: =F44*3.6 -> 5.4068441
A45: P2 | B45: walking | C45: 6 | D45: 3.95 | E45: 2.48 | F45: =D45/E45 -> 1.5927419 | G45: =F45*3.6 -> 5.733871
A46: P2 | B46: walking | C46: 7 | D46: 3.95 | E46: 2.48 | F46: =D46/E46 -> 1.5927419 | G46: =F46*3.6 -> 5.733871
A47: P2 | B47: walking | C47: 8 | D47: 3.95 | E47: 2.46 | F47: =D47/E47 -> 1.6056911 | G47: =F47*3.6 -> 5.7804878
A48: P2 | B48: walking | C48: 9 | D48: 3.95 | E48: 2.43 | F48: =D48/E48 -> 1.6255144 | G48: =F48*3.6 -> 5.8518519
A49: P2 | B49: walking | C49: 10 | D49: 3.95 | E49: 2.53 | F49: =D49/E49 -> 1.5612648 | G49: =F49*3.6 -> 5.6205534
A50: P2 | B50: jogging | C50: 1 | D50: 3.95 | E50: 2.34 | F50: =D50/E50 -> 1.6880342 | G50: =F50*3.6 -> 6.0769231
A51: P2 | B51: jogging | C51: 2 | D51: 3.95 | E51: 1.77 | F51: =D51/E51 -> 2.2316384 | G51: =F51*3.6 -> 8.0338983
A52: P2 | B52: jogging | C52: 3 | D52: 3.95 | E52: 1.62 | F52: =D52/E52 -> 2.4382716 | G52: =F52*3.6 -> 8.7777778
... A69: P2 | B69: running | C69: 10 | D69: 3.95 | E69: 1.36 | F69: =D69/E69 -> 2.9044118 | G69: =F69*3.6 -> 10.455882
A70: P3 | B70: walking | C70: 1 | D70: 3.73 | E70: 3.27 | F70: =D70/E70 -> 1.1406728 | G70: =F70*3.6 -> 4.106422 | H70: shoes size: 41
A71: P3 | B71: walking | C71: 2 | D71: 3.73 | E71: 2.8 | F71: =D71/E71 -> 1.3321429 | G71: =F71*3.6 -> 4.7957143
A72: P3 | B72: walking | C72: 3 | D72: 3.73 | E72: 2.95 | F72: =D72/E72 -> 1.2644068 | G72: =F72*3.6 -> 4.5518644
...

Sheet Summary
A1: Speed summary (auto from Raw)
A2: This sheet summarizes counts and mean speed by participant and activity. If you need SD/median, use a PivotTable in Excel or compute in Python from Raw.
A5: participant | B5: activity | C5: n_trials | D5: mean_speed_mps | E5: mean_speed_kmh | F5: notes
A6: P1 | B6: walking | C6: =COUNTIFS(Raw!$A:$A,$A6,Raw!$B:$B,$B6,Raw!$F:$F,">0") -> 10 | D6: =IF(C6=0,"",AVERAGEIFS(Raw!$F:$F,Raw!$A:$A,$A6,Raw!$B:$B,$B6)) -> 1.715551 | E6: =IF(D6="","",D6*3.6) -> 6.1759837
A7: P1 | B7: jogging | C7: =COUNTIFS(Raw!$A:$A,$A7,Raw!$B:$B,$B7,Raw!$F:$F,">0") -> 11 | D7: =IF(C7=0,"",AVERAGEIFS(Raw!$F:$F,Raw!$A:$A,$A7,Raw!$B:$B,$B7)) -> 3.335386 | E7: =IF(D7="","",D7*3.6) -> 12.00739
A8: P1 | B8: running | C8: =COUNTIFS(Raw!$A:$A,$A8,Raw!$B:$B,$B8,Raw!$F:$F,">0") -> 12 | D8: =IF(C8=0,"",AVERAGEIFS(Raw!$F:$F,Raw!$A:$A,$A8,Raw!$B:$B,$B8)) -> 4.2454713 | E8: =IF(D8="","",D8*3.6) -> 15.283697
A9: P1 | B9: heel_drop | C9: =COUNTIFS(Raw!$A:$A,$A9,Raw!$B:$B,$B9,Raw!$F:$F,">0") -> 0 | D9: =IF(C9=0,"",AVERAGEIFS(Raw!$F:$F,Raw!$A:$A,$A9,Raw!$B:$B,$B9)) | E9: =IF(D9="","",D9*3.6)
A10: P1 | B10: step_drop | C10: =COUNTIFS(Raw!$A:$A,$A10,Raw!$B:$B,$B10,Raw!$F:$F,">0") -> 0 | D10: =IF(C10=0,"",AVERAGEIFS(Raw!$F:$F,Raw!$A:$A,$A10,Raw!$B:$B,$B10)) | E10: =IF(D10="","",D10*3.6)
A11: P2 | B11: walking | C11: =COUNTIFS(Raw!$A:$A,$A11,Raw!$B:$B,$B11,Raw!$F:$F,">0") -> 10 | D11: =IF(C11=0,"",AVERAGEIFS(Raw!$F:$F,Raw!$A:$A,$A11,Raw!$B:$B,$B11)) -> 1.5745558 | E11: =IF(D11="","",D11*3.6) -> 5.6684009
A12: P2 | B12: jogging | C12: =COUNTIFS(Raw!$A:$A,$A12,Raw!$B:$B,$B12,Raw!$F:$F,">0") -> 10 | D12: =IF(C12=0,"",AVERAGEIFS(Raw!$F:$F,Raw!$A:$A,$A12,Raw!$B:$B,$B12)) -> 2.4269559 | E12: =IF(D12="","",D12*3.6) -> 8.7370414
A13: P2 | B13: running | C13: =COUNTIFS(Raw!$A:$A,$A13,Raw!$B:$B,$B13,Raw!$F:$F,">0") -> 10 | D13: =IF(C13=0,"",AVERAGEIFS(Raw!$F:$F,Raw!$A:$A,$A13,Raw!$B:$B,$B13)) -> 2.9828801 | E13: =IF(D13="","",D13*3.6) -> 10.738368
A14: P2 | B14: heel_drop | C14: =COUNTIFS(Raw!$A:$A,$A14,Raw!$B:$B,$B14,Raw!$F:$F,">0") -> 0 | D14: =IF(C14=0,"",AVERAGEIFS(Raw!$F:$F,Raw!$A:$A,$A14,Raw!$B:$B,$B14)) | E14: =IF(D14="","",D14*3.6)
A15: P2 | B15: step_drop | C15: =COUNTIFS(Raw!$A:$A,$A15,Raw!$B:$B,$B15,Raw!$F:$F,">0") -> 0 | D15: =IF(C15=0,"",AVERAGEIFS(Raw!$F:$F,Raw!$A:$A,$A15,Raw!$B:$B,$B15)) | E15: =IF(D15="","",D15*3.6)
A16: P3 | B16: walking | C16: =COUNTIFS(Raw!$A:$A,$A16,Raw!$B:$B,$B16,Raw!$F:$F,">0") -> 10 | D16: =IF(C16=0,"",AVERAGEIFS(Raw!$F:$F,Raw!$A:$A,$A16,Raw!$B:$B,$B16)) -> 1.298653 | E16: =IF(D16="","",D16*3.6) -> 4.6751509
A17: P3 | B17: jogging | C17: =COUNTIFS(Raw!$A:$A,$A17,Raw!$B:$B,$B17,Raw!$F:$F,">0") -> 11 | D17: =IF(C17=0,"",AVERAGEIFS(Raw!$F:$F,Raw!$A:$A,$A17,Raw!$B:$B,$B17)) -> 2.2157868 | E17: =IF(D17="","",D17*3.6) -> 7.9768324
... A55: P10 | B55: step_drop | C55: =COUNTIFS(Raw!$A:$A,$A55,Raw!$B:$B,$B55,Raw!$F:$F,">0") -> 0 | D55: =IF(C55=0,"",AVERAGEIFS(Raw!$F:$F,Raw!$A:$A,$A55,Raw!$B:$B,$B55)) | E55: =IF(D55="","",D55*3.6)
A57: ALL | B57: ALL | C57: =COUNTIF(Raw!$F:$F,">0") -> 303 | D57: =IF(C57=0,"",AVERAGEIF(Raw!$F:$F,">0",Raw!$F:$F)) -> 2.4129885 | E57: =IF(D57="","",D57*3.6) -> 8.6867588 | F57: All participants + activities
